<!DOCTYPE html>
<html lang="ko">

<head>
  <meta charset="UTF-8">
  <meta http-equiv="X-UA-Compatible" content="IE=edge">
  <meta name="viewport" content="width=device-width, initial-scale=1.0">
  <title>Document</title>
  <style>
    body {
      background: rgb(36, 36, 36);
      color: white;
      margin: 0;
      padding: 0;
      text-align: center;
    }
  </style>
  <script>
    // try catch와 에러 핸들링
    // 에러가 발생하면 스크립트는 죽고(즉시 중단), 콘솔에 빨간 에러출력
    // 이게 자바스크립트가 에러 객체를 만들어서 던지는 것!
    // (중요) try catch 문법을 사용하면 스크립트가 죽는것을 방지하고
    // 에러를 잡아서(catch) 더 합당한 처리를 할 수 있음

    // 1. 기본 사용법 및 흐름

    // 1) try 블록 안의 코드가 실행됨
    // 2) 에러가 없다면, try 안의 마지막 줄까지 실행되고, catch 블록은 건너뜀
    // 3) 에러가 발생하면, try 안의 코드의 실행이 중단되고, catch 블록으로 흐름이 넘어감
    // 변수 err는 에러 메시지('설명')가 담긴 에러 객체를 전달 받음

    try {
      // 에러가 발생 가능한 코드들
    } catch (err) {
      // 에러 핸들링 코드
    }

    // try catch 미사용시
    // hahaha; // 에러 발생
    // console.log('다음 로직'); // 실행 안됨

    // try catch 사용시
    try {
      console.log('try 블록 시작');

      hahaha; // 에러 발생
      console.log('try 블록 끝');
    } catch (err) {
      console.log('에러 발생');
      console.error(err);
    }
    console.log('다음 로직');
    // 이렇게 try 블록 안에서 에러가 발생해도 catch에서 에러를 처리하기 때문에 스크립트는 죽지 않음

    // 2. 에러 객체
    // 에러가 발생하면 자바스크립트는 에러 상세내용이 담긴 객체를 생성
    // catch 블록에 에러 객체를 인수로 전달
    try {
      lalala; // 에러, 변수가 정의되지 않음
    } catch (err) {
      console.log(err.name); // 에러 이름, 여기서는 ReferenceError
      console.log(err.message); // 에러 상세 내용을 담은 메세지, 여기서는 lalala is not undefined

      // 에러 전체를 출력 시 에러 객체는 "name: message"형태의 문자열로 반환됨
      console.log(err);
    }

    // 3. 선택적 catch 바인딩(할당) (ES2019)
    // 에러에 대한 자세한 정보가 필요하지 않으면, catch에서 이를 생략 가능
    try {

    } catch { // <-- 변수(err) 없이 쓸수 있음

    }

    // 4. try catch 활용 예
    // JSON.parse(): 주로 서버 등에서 전달받은 JSON데이터를 자바스크립트 객체로 변환할 때 사용

    const json = '{"name":"KIM","age":"27"}'; // 서버로부터 받은 데이터라 가정

    const user = JSON.parse(json); // 전달받은 문자열을 자바객체로 변환

    // 문자열로 전달받은 user가 속성을 가진 객체가 된다.
    console.log(user);
    console.log(user.name);
    console.log(user.age);

    // 잘못된 형식의 json인 경우, JSON.parse()는 에러를 만들기 때문에 스크립트가 죽음(즉시 중단)
    const badJson = '{bad json}';
    try {
      const user2 = JSON.parse(badJson) // 에러가 발생
      console.log(user2); // 이 코드는 실행 안됨
    } catch (e) {
      console.log('데이터에 에러가 있어 재요청을 시도합니당...');
      console.error(e.name);
      console.log(e.message);
      // 예제에서는 간단히 로그만 찍었지만
      // 새로운 넷웤 요청 보내기, 사용자에게 다른 대안을 제시하기 등 구체적인 에러 핸들링을 할 수 있다.
    }

    // 5. 직접 에러를 만들어서 던지기

    const shortJson = '{"AGE":30}'; // 불완전한 데이터

    try {
      const user = JSON.parse(shortJson); // <-- 에러 없음
      console.log(user.name); // 이름 속성이 없음
      // 아니면 넷웤 응답이 왔는데 NOK 일 떄(에러는 없지만 문제를 유발하는 상황일 때)
    } catch (e) {
      console.log('실행되지 않습니다.');
    }

    // 위와 같은 상황에서 에러는 없지만 에러 처리를 통합하고 싶을 때
    // throw 연산자로 에러 던지기
    // throw <error object>

    // (참고) error object 
    // 자바스크립트는 Error,SyntaxError,ReferenceError,TypeError 등의 표준 에러 객체 생성자를 지원
    // 이 생성자들을 이용해 여러 객체를 만들 수도 있음

    // let error1 = new Error('에러 발생');
    // error1 = new SyntaxError('문법 에러 발생');
    // error1 = new ReferenceError('참조 에러 발생');
    // console.log(error1.name);
    // console.log(error1.message);

    // throw 적용
    try {
      const user = JSON.parse(shortJson); // <-- 에러 없음
      if (!user.name) {
        throw new SyntaxError("불완전한 데이터 : 이름없음"); // 에러를 만들어서 던짐
      }
      console.log(user.name); // 이름 속성이 없음
    } catch (e) {
      console.error(e);

      // if (e instanceof syntaxError) {

      // }
    }

    // 6. finally {}
    // 에러 발생 유무와 상관없이 무적권실행
    // 무적권 마무리 지어야 하는 작업 시 사용(ex: 작업 내역 초기화, 리소스 연결 끊기)
    try {
      // ... 코드를 실행 ... //
    } catch (error) {
      // ... 에러 핸들링 ... //
    } finally {
      // ... 항상 실행 ... //
    }

    // finally 사용시
    // try {
    //   console.log('try 블록 시작');
    //   if (confirm('에러를 생성하겠습니까?!'))
    //     errorCode();
    // } catch (error) {
    //   console.log('catch!!');
    // } finally {
    //   console.log('finally');
    // }

    // finally와 return
    // finally는 try catch 문을 빠져나가는 어떤 경우에도 실행됨
    // return을 사용해 빠져나가려는 경우도 마찬가지
    function func() {
      try {
        return 1;
      } catch (e) {
        console.log(e);
      } finally {
        console.log('finally 블록 무적권 실행!');
      }
    }
    console.log(func());



  </script>
</head>

<body>

</body>

</html>